const f = () => { 
         try { 
                 let a = 0; 
                 console.log("Program ran successfully") 
                 return 
         } 
         catch (err) { 
                 console.log("This is an error") 
                 console.log(p) 
         } 
         finally { 
                 console.log("I will run for sure don't worry") 
                 // Close the file 
                 // Exit the Loop 
                 // Write to the log file 
         } 
 } 
  
 f() 
 console.log("End")
